[2025-05-24T04:34:26.820+0530] {task_context_logger.py:104} ERROR - Executor reports task instance <TaskInstance: order_monitoring_dag.run_dbt_models manual__2025-05-23T23:04:20.449962+00:00 [queued]> finished (failed) although the task says it's queued. (Info: None) Was the task killed externally?
