[2025-05-27T17:55:09.558+0530] {taskinstance.py:1956} INFO - Dependencies all met for dep_context=non-requeueable deps ti=<TaskInstance: order_monitoring_dag12.run_dbt_models scheduled__2025-05-27T11:00:00+00:00 [queued]>
[2025-05-27T17:55:09.563+0530] {taskinstance.py:1956} INFO - Dependencies all met for dep_context=requeueable deps ti=<TaskInstance: order_monitoring_dag12.run_dbt_models scheduled__2025-05-27T11:00:00+00:00 [queued]>
[2025-05-27T17:55:09.563+0530] {taskinstance.py:2170} INFO - Starting attempt 1 of 1
[2025-05-27T17:55:09.573+0530] {taskinstance.py:2191} INFO - Executing <Task(BashOperator): run_dbt_models> on 2025-05-27 11:00:00+00:00
[2025-05-27T17:55:09.577+0530] {standard_task_runner.py:60} INFO - Started process 24032 to run task
[2025-05-27T17:55:09.584+0530] {standard_task_runner.py:87} INFO - Running: ['airflow', 'tasks', 'run', 'order_monitoring_dag12', 'run_dbt_models', 'scheduled__2025-05-27T11:00:00+00:00', '--job-id', '5', '--raw', '--subdir', 'DAGS_FOLDER/order_monitoring_dag.py', '--cfg-path', '/var/folders/7w/779kl2wj7p9971zq3yv085jm0000gn/T/tmpr7vdmnlx']
[2025-05-27T17:55:09.585+0530] {standard_task_runner.py:88} INFO - Job 5: Subtask run_dbt_models
[2025-05-27T17:55:09.624+0530] {task_command.py:423} INFO - Running <TaskInstance: order_monitoring_dag12.run_dbt_models scheduled__2025-05-27T11:00:00+00:00 [running]> on host zafars-macbook-pro.local
[2025-05-27T17:55:09.670+0530] {taskinstance.py:2480} INFO - Exporting env vars: AIRFLOW_CTX_DAG_EMAIL='imamzafar100@gmail.com' AIRFLOW_CTX_DAG_OWNER='airflow' AIRFLOW_CTX_DAG_ID='order_monitoring_dag12' AIRFLOW_CTX_TASK_ID='run_dbt_models' AIRFLOW_CTX_EXECUTION_DATE='2025-05-27T11:00:00+00:00' AIRFLOW_CTX_TRY_NUMBER='1' AIRFLOW_CTX_DAG_RUN_ID='scheduled__2025-05-27T11:00:00+00:00'
[2025-05-27T17:55:09.672+0530] {subprocess.py:63} INFO - Tmp dir root location: /var/folders/7w/779kl2wj7p9971zq3yv085jm0000gn/T
[2025-05-27T17:55:09.673+0530] {subprocess.py:75} INFO - Running command: ['/bin/bash', '-c', 'source "/Users/zafarimam/Documents/E-Commerce Order Pipeline/airflow_venv_39/bin/activate" && cd "/Users/zafarimam/Documents/E-Commerce Order Pipeline/dbt_ecommerce" && dbt run']
[2025-05-27T17:55:09.678+0530] {subprocess.py:86} INFO - Output:
[2025-05-27T17:55:13.642+0530] {subprocess.py:93} INFO - Traceback (most recent call last):
[2025-05-27T17:55:13.643+0530] {subprocess.py:93} INFO -   File "/Library/Frameworks/Python.framework/Versions/3.12/bin/dbt", line 5, in <module>
[2025-05-27T17:55:13.643+0530] {subprocess.py:93} INFO -     from dbt.cli.main import cli
[2025-05-27T17:55:13.644+0530] {subprocess.py:93} INFO -   File "/Library/Frameworks/Python.framework/Versions/3.12/lib/python3.12/site-packages/dbt/cli/__init__.py", line 1, in <module>
[2025-05-27T17:55:13.644+0530] {subprocess.py:93} INFO -     from .main import cli as dbt_cli  # noqa
[2025-05-27T17:55:13.644+0530] {subprocess.py:93} INFO -     ^^^^^^^^^^^^^^^^^^^^^^^^^^^^^^^^
[2025-05-27T17:55:13.645+0530] {subprocess.py:93} INFO -   File "/Library/Frameworks/Python.framework/Versions/3.12/lib/python3.12/site-packages/dbt/cli/main.py", line 13, in <module>
[2025-05-27T17:55:13.645+0530] {subprocess.py:93} INFO -     from dbt.artifacts.schemas.run import RunExecutionResult
[2025-05-27T17:55:13.645+0530] {subprocess.py:93} INFO -   File "/Library/Frameworks/Python.framework/Versions/3.12/lib/python3.12/site-packages/dbt/artifacts/schemas/run/__init__.py", line 2, in <module>
[2025-05-27T17:55:13.646+0530] {subprocess.py:93} INFO -     from dbt.artifacts.schemas.run.v5.run import *  # noqa
[2025-05-27T17:55:13.646+0530] {subprocess.py:93} INFO -     ^^^^^^^^^^^^^^^^^^^^^^^^^^^^^^^^^^^^^^^^^^^^^^
[2025-05-27T17:55:13.646+0530] {subprocess.py:93} INFO -   File "/Library/Frameworks/Python.framework/Versions/3.12/lib/python3.12/site-packages/dbt/artifacts/schemas/run/v5/run.py", line 23, in <module>
[2025-05-27T17:55:13.647+0530] {subprocess.py:93} INFO -     from dbt.artifacts.schemas.results import (
[2025-05-27T17:55:13.647+0530] {subprocess.py:93} INFO -   File "/Library/Frameworks/Python.framework/Versions/3.12/lib/python3.12/site-packages/dbt/artifacts/schemas/results.py", line 5, in <module>
[2025-05-27T17:55:13.647+0530] {subprocess.py:93} INFO -     from dbt.contracts.graph.nodes import ResultNode
[2025-05-27T17:55:13.648+0530] {subprocess.py:93} INFO -   File "/Library/Frameworks/Python.framework/Versions/3.12/lib/python3.12/site-packages/dbt/contracts/graph/nodes.py", line 67, in <module>
[2025-05-27T17:55:13.648+0530] {subprocess.py:93} INFO -     from dbt.contracts.graph.unparsed import (
[2025-05-27T17:55:13.648+0530] {subprocess.py:93} INFO -   File "/Library/Frameworks/Python.framework/Versions/3.12/lib/python3.12/site-packages/dbt/contracts/graph/unparsed.py", line 9, in <module>
[2025-05-27T17:55:13.648+0530] {subprocess.py:93} INFO -     from dbt import deprecations
[2025-05-27T17:55:13.649+0530] {subprocess.py:93} INFO -   File "/Library/Frameworks/Python.framework/Versions/3.12/lib/python3.12/site-packages/dbt/deprecations.py", line 4, in <module>
[2025-05-27T17:55:13.649+0530] {subprocess.py:93} INFO -     import dbt.tracking
[2025-05-27T17:55:13.650+0530] {subprocess.py:93} INFO -   File "/Library/Frameworks/Python.framework/Versions/3.12/lib/python3.12/site-packages/dbt/tracking.py", line 20, in <module>
[2025-05-27T17:55:13.650+0530] {subprocess.py:93} INFO -     from dbt.events.types import (
[2025-05-27T17:55:13.650+0530] {subprocess.py:93} INFO -   File "/Library/Frameworks/Python.framework/Versions/3.12/lib/python3.12/site-packages/dbt/events/__init__.py", line 4, in <module>
[2025-05-27T17:55:13.651+0530] {subprocess.py:93} INFO -     import dbt.events.types as core_dbt_event_types
[2025-05-27T17:55:13.651+0530] {subprocess.py:93} INFO -   File "/Library/Frameworks/Python.framework/Versions/3.12/lib/python3.12/site-packages/dbt/events/types.py", line 4, in <module>
[2025-05-27T17:55:13.651+0530] {subprocess.py:93} INFO -     from dbt.events.base_types import (
[2025-05-27T17:55:13.652+0530] {subprocess.py:93} INFO -   File "/Library/Frameworks/Python.framework/Versions/3.12/lib/python3.12/site-packages/dbt/events/base_types.py", line 2, in <module>
[2025-05-27T17:55:13.652+0530] {subprocess.py:93} INFO -     from dbt.events import core_types_pb2
[2025-05-27T17:55:13.652+0530] {subprocess.py:93} INFO -   File "/Library/Frameworks/Python.framework/Versions/3.12/lib/python3.12/site-packages/dbt/events/core_types_pb2.py", line 9, in <module>
[2025-05-27T17:55:13.653+0530] {subprocess.py:93} INFO -     from google.protobuf import runtime_version as _runtime_version
[2025-05-27T17:55:13.653+0530] {subprocess.py:93} INFO - ImportError: cannot import name 'runtime_version' from 'google.protobuf' (/Library/Frameworks/Python.framework/Versions/3.12/lib/python3.12/site-packages/google/protobuf/__init__.py)
[2025-05-27T17:55:13.763+0530] {subprocess.py:97} INFO - Command exited with return code 1
[2025-05-27T17:55:13.771+0530] {taskinstance.py:2698} ERROR - Task failed with exception
Traceback (most recent call last):
  File "/Users/zafarimam/Documents/E-Commerce Order Pipeline/airflow_venv_39/lib/python3.9/site-packages/airflow/models/taskinstance.py", line 433, in _execute_task
    result = execute_callable(context=context, **execute_callable_kwargs)
  File "/Users/zafarimam/Documents/E-Commerce Order Pipeline/airflow_venv_39/lib/python3.9/site-packages/airflow/operators/bash.py", line 212, in execute
    raise AirflowException(
airflow.exceptions.AirflowException: Bash command failed. The command returned a non-zero exit code 1.
[2025-05-27T17:55:13.775+0530] {taskinstance.py:1138} INFO - Marking task as FAILED. dag_id=order_monitoring_dag12, task_id=run_dbt_models, execution_date=20250527T110000, start_date=20250527T122509, end_date=20250527T122513
[2025-05-27T17:55:13.799+0530] {logging_mixin.py:188} WARNING - /Users/zafarimam/Documents/E-Commerce Order Pipeline/airflow_venv_39/lib/python3.9/site-packages/airflow/utils/email.py:154 RemovedInAirflow3Warning: Fetching SMTP credentials from configuration variables will be deprecated in a future release. Please set credentials using a connection instead.
[2025-05-27T17:55:13.800+0530] {email.py:270} INFO - Email alerting: attempt 1
[2025-05-27T17:55:13.805+0530] {email.py:270} INFO - Email alerting: attempt 1
[2025-05-27T17:55:13.806+0530] {taskinstance.py:826} ERROR - Failed to send email to: ['imamzafar100@gmail.com']
Traceback (most recent call last):
  File "/Users/zafarimam/Documents/E-Commerce Order Pipeline/airflow_venv_39/lib/python3.9/site-packages/airflow/models/taskinstance.py", line 2334, in _run_raw_task
    self._execute_task_with_callbacks(context, test_mode, session=session)
  File "/Users/zafarimam/Documents/E-Commerce Order Pipeline/airflow_venv_39/lib/python3.9/site-packages/airflow/models/taskinstance.py", line 2499, in _execute_task_with_callbacks
    result = self._execute_task(context, task_orig)
  File "/Users/zafarimam/Documents/E-Commerce Order Pipeline/airflow_venv_39/lib/python3.9/site-packages/airflow/models/taskinstance.py", line 2516, in _execute_task
    return _execute_task(self, context, task_orig)
  File "/Users/zafarimam/Documents/E-Commerce Order Pipeline/airflow_venv_39/lib/python3.9/site-packages/airflow/models/taskinstance.py", line 433, in _execute_task
    result = execute_callable(context=context, **execute_callable_kwargs)
  File "/Users/zafarimam/Documents/E-Commerce Order Pipeline/airflow_venv_39/lib/python3.9/site-packages/airflow/operators/bash.py", line 212, in execute
    raise AirflowException(
airflow.exceptions.AirflowException: Bash command failed. The command returned a non-zero exit code 1.

During handling of the above exception, another exception occurred:

Traceback (most recent call last):
  File "/Users/zafarimam/Documents/E-Commerce Order Pipeline/airflow_venv_39/lib/python3.9/site-packages/airflow/models/taskinstance.py", line 1000, in _email_alert
    send_email(task.email, subject, html_content)
  File "/Users/zafarimam/Documents/E-Commerce Order Pipeline/airflow_venv_39/lib/python3.9/site-packages/airflow/utils/email.py", line 80, in send_email
    return backend(
  File "/Users/zafarimam/Documents/E-Commerce Order Pipeline/airflow_venv_39/lib/python3.9/site-packages/airflow/utils/email.py", line 154, in send_email_smtp
    send_mime_email(e_from=mail_from, e_to=recipients, mime_msg=msg, conn_id=conn_id, dryrun=dryrun)
  File "/Users/zafarimam/Documents/E-Commerce Order Pipeline/airflow_venv_39/lib/python3.9/site-packages/airflow/utils/email.py", line 272, in send_mime_email
    smtp_conn = _get_smtp_connection(smtp_host, smtp_port, smtp_timeout, smtp_ssl)
  File "/Users/zafarimam/Documents/E-Commerce Order Pipeline/airflow_venv_39/lib/python3.9/site-packages/airflow/utils/email.py", line 316, in _get_smtp_connection
    return smtplib.SMTP(host=host, port=port, timeout=timeout)
  File "/usr/local/Cellar/python@3.9/3.9.22_1/Frameworks/Python.framework/Versions/3.9/lib/python3.9/smtplib.py", line 255, in __init__
    (code, msg) = self.connect(host, port)
  File "/usr/local/Cellar/python@3.9/3.9.22_1/Frameworks/Python.framework/Versions/3.9/lib/python3.9/smtplib.py", line 341, in connect
    self.sock = self._get_socket(host, port, self.timeout)
  File "/usr/local/Cellar/python@3.9/3.9.22_1/Frameworks/Python.framework/Versions/3.9/lib/python3.9/smtplib.py", line 312, in _get_socket
    return socket.create_connection((host, port), timeout,
  File "/usr/local/Cellar/python@3.9/3.9.22_1/Frameworks/Python.framework/Versions/3.9/lib/python3.9/socket.py", line 856, in create_connection
    raise err
  File "/usr/local/Cellar/python@3.9/3.9.22_1/Frameworks/Python.framework/Versions/3.9/lib/python3.9/socket.py", line 844, in create_connection
    sock.connect(sa)
ConnectionRefusedError: [Errno 61] Connection refused

During handling of the above exception, another exception occurred:

Traceback (most recent call last):
  File "/Users/zafarimam/Documents/E-Commerce Order Pipeline/airflow_venv_39/lib/python3.9/site-packages/airflow/models/taskinstance.py", line 824, in _handle_failure
    task_instance.email_alert(error, failure_context["task"])
  File "/Users/zafarimam/Documents/E-Commerce Order Pipeline/airflow_venv_39/lib/python3.9/site-packages/airflow/models/taskinstance.py", line 2946, in email_alert
    _email_alert(task_instance=self, exception=exception, task=task)
  File "/Users/zafarimam/Documents/E-Commerce Order Pipeline/airflow_venv_39/lib/python3.9/site-packages/airflow/models/taskinstance.py", line 1002, in _email_alert
    send_email(task.email, subject, html_content_err)
  File "/Users/zafarimam/Documents/E-Commerce Order Pipeline/airflow_venv_39/lib/python3.9/site-packages/airflow/utils/email.py", line 80, in send_email
    return backend(
  File "/Users/zafarimam/Documents/E-Commerce Order Pipeline/airflow_venv_39/lib/python3.9/site-packages/airflow/utils/email.py", line 154, in send_email_smtp
    send_mime_email(e_from=mail_from, e_to=recipients, mime_msg=msg, conn_id=conn_id, dryrun=dryrun)
  File "/Users/zafarimam/Documents/E-Commerce Order Pipeline/airflow_venv_39/lib/python3.9/site-packages/airflow/utils/email.py", line 272, in send_mime_email
    smtp_conn = _get_smtp_connection(smtp_host, smtp_port, smtp_timeout, smtp_ssl)
  File "/Users/zafarimam/Documents/E-Commerce Order Pipeline/airflow_venv_39/lib/python3.9/site-packages/airflow/utils/email.py", line 316, in _get_smtp_connection
    return smtplib.SMTP(host=host, port=port, timeout=timeout)
  File "/usr/local/Cellar/python@3.9/3.9.22_1/Frameworks/Python.framework/Versions/3.9/lib/python3.9/smtplib.py", line 255, in __init__
    (code, msg) = self.connect(host, port)
  File "/usr/local/Cellar/python@3.9/3.9.22_1/Frameworks/Python.framework/Versions/3.9/lib/python3.9/smtplib.py", line 341, in connect
    self.sock = self._get_socket(host, port, self.timeout)
  File "/usr/local/Cellar/python@3.9/3.9.22_1/Frameworks/Python.framework/Versions/3.9/lib/python3.9/smtplib.py", line 312, in _get_socket
    return socket.create_connection((host, port), timeout,
  File "/usr/local/Cellar/python@3.9/3.9.22_1/Frameworks/Python.framework/Versions/3.9/lib/python3.9/socket.py", line 856, in create_connection
    raise err
  File "/usr/local/Cellar/python@3.9/3.9.22_1/Frameworks/Python.framework/Versions/3.9/lib/python3.9/socket.py", line 844, in create_connection
    sock.connect(sa)
ConnectionRefusedError: [Errno 61] Connection refused
[2025-05-27T17:55:13.817+0530] {standard_task_runner.py:107} ERROR - Failed to execute job 5 for task run_dbt_models (Bash command failed. The command returned a non-zero exit code 1.; 24032)
[2025-05-27T17:55:13.853+0530] {local_task_job_runner.py:234} INFO - Task exited with return code 1
[2025-05-27T17:55:13.871+0530] {taskinstance.py:3280} INFO - 0 downstream tasks scheduled from follow-on schedule check
