[2025-05-24T04:25:07.488+0530] {local_task_job_runner.py:120} INFO - ::group::Pre task execution logs
[2025-05-24T04:25:07.516+0530] {taskinstance.py:2073} INFO - Dependencies all met for dep_context=non-requeueable deps ti=<TaskInstance: order_monitoring_dag.run_dbt_models manual__2025-05-23T22:55:00.730344+00:00 [queued]>
[2025-05-24T04:25:07.521+0530] {taskinstance.py:2073} INFO - Dependencies all met for dep_context=requeueable deps ti=<TaskInstance: order_monitoring_dag.run_dbt_models manual__2025-05-23T22:55:00.730344+00:00 [queued]>
[2025-05-24T04:25:07.521+0530] {taskinstance.py:2303} INFO - Starting attempt 1 of 1
[2025-05-24T04:25:07.530+0530] {taskinstance.py:2327} INFO - Executing <Task(BashOperator): run_dbt_models> on 2025-05-23 22:55:00.730344+00:00
[2025-05-24T04:25:07.541+0530] {logging_mixin.py:188} WARNING - /Library/Frameworks/Python.framework/Versions/3.12/lib/python3.12/site-packages/airflow/task/task_runner/standard_task_runner.py:61 DeprecationWarning: This process (pid=15724) is multi-threaded, use of fork() may lead to deadlocks in the child.
[2025-05-24T04:25:07.542+0530] {standard_task_runner.py:63} INFO - Started process 15725 to run task
[2025-05-24T04:25:07.541+0530] {standard_task_runner.py:90} INFO - Running: ['airflow', 'tasks', 'run', 'order_monitoring_dag', 'run_dbt_models', 'manual__2025-05-23T22:55:00.730344+00:00', '--job-id', '4', '--raw', '--subdir', 'DAGS_FOLDER/order_monitoring_dag.py', '--cfg-path', '/var/folders/7w/779kl2wj7p9971zq3yv085jm0000gn/T/tmp849ttovs']
[2025-05-24T04:25:07.544+0530] {standard_task_runner.py:91} INFO - Job 4: Subtask run_dbt_models
[2025-05-24T04:25:07.581+0530] {task_command.py:426} INFO - Running <TaskInstance: order_monitoring_dag.run_dbt_models manual__2025-05-23T22:55:00.730344+00:00 [running]> on host zafars-macbook-pro.local
[2025-05-24T04:25:07.636+0530] {taskinstance.py:2644} INFO - Exporting env vars: AIRFLOW_CTX_DAG_OWNER='airflow' AIRFLOW_CTX_DAG_ID='order_monitoring_dag' AIRFLOW_CTX_TASK_ID='run_dbt_models' AIRFLOW_CTX_EXECUTION_DATE='2025-05-23T22:55:00.730344+00:00' AIRFLOW_CTX_TRY_NUMBER='1' AIRFLOW_CTX_DAG_RUN_ID='manual__2025-05-23T22:55:00.730344+00:00'
[2025-05-24T04:25:07.638+0530] {taskinstance.py:430} INFO - ::endgroup::
[2025-05-24T04:25:07.639+0530] {subprocess.py:63} INFO - Tmp dir root location: /var/folders/7w/779kl2wj7p9971zq3yv085jm0000gn/T
[2025-05-24T04:25:07.640+0530] {subprocess.py:75} INFO - Running command: ['/bin/bash', '-c', '/Users/zafarimam/Documents/E-Commerce Order Pipeline/dbt_ecommerce && dbt run']
[2025-05-24T04:25:07.646+0530] {subprocess.py:86} INFO - Output:
[2025-05-24T04:25:07.651+0530] {subprocess.py:93} INFO - /bin/bash: /Users/zafarimam/Documents/E-Commerce: No such file or directory
[2025-05-24T04:25:07.651+0530] {subprocess.py:97} INFO - Command exited with return code 127
[2025-05-24T04:25:07.652+0530] {taskinstance.py:441} INFO - ::group::Post task execution logs
[2025-05-24T04:25:07.658+0530] {taskinstance.py:2890} ERROR - Task failed with exception
Traceback (most recent call last):
  File "/Library/Frameworks/Python.framework/Versions/3.12/lib/python3.12/site-packages/airflow/models/taskinstance.py", line 465, in _execute_task
    result = _execute_callable(context=context, **execute_callable_kwargs)
             ^^^^^^^^^^^^^^^^^^^^^^^^^^^^^^^^^^^^^^^^^^^^^^^^^^^^^^^^^^^^^
  File "/Library/Frameworks/Python.framework/Versions/3.12/lib/python3.12/site-packages/airflow/models/taskinstance.py", line 432, in _execute_callable
    return execute_callable(context=context, **execute_callable_kwargs)
           ^^^^^^^^^^^^^^^^^^^^^^^^^^^^^^^^^^^^^^^^^^^^^^^^^^^^^^^^^^^^
  File "/Library/Frameworks/Python.framework/Versions/3.12/lib/python3.12/site-packages/airflow/models/baseoperator.py", line 400, in wrapper
    return func(self, *args, **kwargs)
           ^^^^^^^^^^^^^^^^^^^^^^^^^^^
  File "/Library/Frameworks/Python.framework/Versions/3.12/lib/python3.12/site-packages/airflow/operators/bash.py", line 243, in execute
    raise AirflowException(
airflow.exceptions.AirflowException: Bash command failed. The command returned a non-zero exit code 127.
[2025-05-24T04:25:07.662+0530] {taskinstance.py:1205} INFO - Marking task as FAILED. dag_id=order_monitoring_dag, task_id=run_dbt_models, execution_date=20250523T225500, start_date=20250523T225507, end_date=20250523T225507
[2025-05-24T04:25:07.670+0530] {standard_task_runner.py:110} ERROR - Failed to execute job 4 for task run_dbt_models (Bash command failed. The command returned a non-zero exit code 127.; 15725)
[2025-05-24T04:25:07.680+0530] {local_task_job_runner.py:240} INFO - Task exited with return code 1
[2025-05-24T04:25:07.695+0530] {taskinstance.py:3482} INFO - 0 downstream tasks scheduled from follow-on schedule check
[2025-05-24T04:25:07.699+0530] {local_task_job_runner.py:222} INFO - ::endgroup::
