[2025-05-24T05:30:37.811+0530] {local_task_job_runner.py:120} INFO - ::group::Pre task execution logs
[2025-05-24T05:30:37.838+0530] {taskinstance.py:2073} INFO - Dependencies all met for dep_context=non-requeueable deps ti=<TaskInstance: order_monitoring_dag1.email_delayed_orders manual__2025-05-24T00:00:13.996933+00:00 [queued]>
[2025-05-24T05:30:37.843+0530] {taskinstance.py:2073} INFO - Dependencies all met for dep_context=requeueable deps ti=<TaskInstance: order_monitoring_dag1.email_delayed_orders manual__2025-05-24T00:00:13.996933+00:00 [queued]>
[2025-05-24T05:30:37.843+0530] {taskinstance.py:2303} INFO - Starting attempt 1 of 1
[2025-05-24T05:30:37.852+0530] {taskinstance.py:2327} INFO - Executing <Task(EmailOperator): email_delayed_orders> on 2025-05-24 00:00:13.996933+00:00
[2025-05-24T05:30:37.863+0530] {logging_mixin.py:188} WARNING - /Library/Frameworks/Python.framework/Versions/3.12/lib/python3.12/site-packages/airflow/task/task_runner/standard_task_runner.py:61 DeprecationWarning: This process (pid=20820) is multi-threaded, use of fork() may lead to deadlocks in the child.
[2025-05-24T05:30:37.864+0530] {standard_task_runner.py:63} INFO - Started process 20821 to run task
[2025-05-24T05:30:37.863+0530] {standard_task_runner.py:90} INFO - Running: ['airflow', 'tasks', 'run', 'order_monitoring_dag1', 'email_delayed_orders', 'manual__2025-05-24T00:00:13.996933+00:00', '--job-id', '21', '--raw', '--subdir', 'DAGS_FOLDER/order_monitoring_dag.py', '--cfg-path', '/var/folders/7w/779kl2wj7p9971zq3yv085jm0000gn/T/tmpqgi3n4np']
[2025-05-24T05:30:37.867+0530] {standard_task_runner.py:91} INFO - Job 21: Subtask email_delayed_orders
[2025-05-24T05:30:37.906+0530] {task_command.py:426} INFO - Running <TaskInstance: order_monitoring_dag1.email_delayed_orders manual__2025-05-24T00:00:13.996933+00:00 [running]> on host zafars-macbook-pro.local
[2025-05-24T05:30:37.958+0530] {taskinstance.py:2644} INFO - Exporting env vars: AIRFLOW_CTX_DAG_OWNER='airflow' AIRFLOW_CTX_DAG_ID='order_monitoring_dag1' AIRFLOW_CTX_TASK_ID='email_delayed_orders' AIRFLOW_CTX_EXECUTION_DATE='2025-05-24T00:00:13.996933+00:00' AIRFLOW_CTX_TRY_NUMBER='1' AIRFLOW_CTX_DAG_RUN_ID='manual__2025-05-24T00:00:13.996933+00:00'
[2025-05-24T05:30:37.960+0530] {taskinstance.py:430} INFO - ::endgroup::
[2025-05-24T05:30:37.971+0530] {logging_mixin.py:188} WARNING - /Library/Frameworks/Python.framework/Versions/3.12/lib/python3.12/site-packages/airflow/utils/email.py:154 RemovedInAirflow3Warning: Fetching SMTP credentials from configuration variables will be deprecated in a future release. Please set credentials using a connection instead.
[2025-05-24T05:30:37.971+0530] {configuration.py:1050} WARNING - section/key [smtp/smtp_user] not found in config
[2025-05-24T05:30:37.972+0530] {email.py:271} INFO - Email alerting: attempt 1
[2025-05-24T05:30:37.973+0530] {taskinstance.py:441} INFO - ::group::Post task execution logs
[2025-05-24T05:30:37.974+0530] {taskinstance.py:2890} ERROR - Task failed with exception
Traceback (most recent call last):
  File "/Library/Frameworks/Python.framework/Versions/3.12/lib/python3.12/site-packages/airflow/models/taskinstance.py", line 465, in _execute_task
    result = _execute_callable(context=context, **execute_callable_kwargs)
             ^^^^^^^^^^^^^^^^^^^^^^^^^^^^^^^^^^^^^^^^^^^^^^^^^^^^^^^^^^^^^
  File "/Library/Frameworks/Python.framework/Versions/3.12/lib/python3.12/site-packages/airflow/models/taskinstance.py", line 432, in _execute_callable
    return execute_callable(context=context, **execute_callable_kwargs)
           ^^^^^^^^^^^^^^^^^^^^^^^^^^^^^^^^^^^^^^^^^^^^^^^^^^^^^^^^^^^^
  File "/Library/Frameworks/Python.framework/Versions/3.12/lib/python3.12/site-packages/airflow/models/baseoperator.py", line 400, in wrapper
    return func(self, *args, **kwargs)
           ^^^^^^^^^^^^^^^^^^^^^^^^^^^
  File "/Library/Frameworks/Python.framework/Versions/3.12/lib/python3.12/site-packages/airflow/operators/email.py", line 79, in execute
    send_email(
  File "/Library/Frameworks/Python.framework/Versions/3.12/lib/python3.12/site-packages/airflow/utils/email.py", line 80, in send_email
    return backend(
           ^^^^^^^^
  File "/Library/Frameworks/Python.framework/Versions/3.12/lib/python3.12/site-packages/airflow/utils/email.py", line 154, in send_email_smtp
    send_mime_email(e_from=mail_from, e_to=recipients, mime_msg=msg, conn_id=conn_id, dryrun=dryrun)
  File "/Library/Frameworks/Python.framework/Versions/3.12/lib/python3.12/site-packages/airflow/utils/email.py", line 273, in send_mime_email
    smtp_conn = _get_smtp_connection(smtp_host, smtp_port, smtp_timeout, smtp_ssl)
                ^^^^^^^^^^^^^^^^^^^^^^^^^^^^^^^^^^^^^^^^^^^^^^^^^^^^^^^^^^^^^^^^^^
  File "/Library/Frameworks/Python.framework/Versions/3.12/lib/python3.12/site-packages/airflow/utils/email.py", line 317, in _get_smtp_connection
    return smtplib.SMTP(host=host, port=port, timeout=timeout)
           ^^^^^^^^^^^^^^^^^^^^^^^^^^^^^^^^^^^^^^^^^^^^^^^^^^^
  File "/Library/Frameworks/Python.framework/Versions/3.12/lib/python3.12/smtplib.py", line 255, in __init__
    (code, msg) = self.connect(host, port)
                  ^^^^^^^^^^^^^^^^^^^^^^^^
  File "/Library/Frameworks/Python.framework/Versions/3.12/lib/python3.12/smtplib.py", line 341, in connect
    self.sock = self._get_socket(host, port, self.timeout)
                ^^^^^^^^^^^^^^^^^^^^^^^^^^^^^^^^^^^^^^^^^^
  File "/Library/Frameworks/Python.framework/Versions/3.12/lib/python3.12/smtplib.py", line 312, in _get_socket
    return socket.create_connection((host, port), timeout,
           ^^^^^^^^^^^^^^^^^^^^^^^^^^^^^^^^^^^^^^^^^^^^^^^
  File "/Library/Frameworks/Python.framework/Versions/3.12/lib/python3.12/socket.py", line 865, in create_connection
    raise exceptions[0]
  File "/Library/Frameworks/Python.framework/Versions/3.12/lib/python3.12/socket.py", line 850, in create_connection
    sock.connect(sa)
ConnectionRefusedError: [Errno 61] Connection refused
[2025-05-24T05:30:37.980+0530] {taskinstance.py:1205} INFO - Marking task as FAILED. dag_id=order_monitoring_dag1, task_id=email_delayed_orders, execution_date=20250524T000013, start_date=20250524T000037, end_date=20250524T000037
[2025-05-24T05:30:37.986+0530] {standard_task_runner.py:110} ERROR - Failed to execute job 21 for task email_delayed_orders ([Errno 61] Connection refused; 20821)
[2025-05-24T05:30:38.002+0530] {local_task_job_runner.py:240} INFO - Task exited with return code 1
[2025-05-24T05:30:38.015+0530] {taskinstance.py:3482} INFO - 0 downstream tasks scheduled from follow-on schedule check
[2025-05-24T05:30:38.016+0530] {local_task_job_runner.py:222} INFO - ::endgroup::
